{"uuid": "03efb8e8-8747-4e59-9091-b2bc9aa2c236", "children": ["a64dec92-93fe-45c8-8411-76a631576957", "0825a1e1-d485-4dfa-b668-626035190d58"], "befores": [{"name": "appium_driver", "status": "passed", "start": 1741887089298, "stop": 1741887095268}], "afters": [{"name": "appium_driver::0", "status": "broken", "statusDetails": {"message": "selenium.common.exceptions.WebDriverException: Message: An unknown server-side error occurred while processing the command. Original error: Error executing adbExec. Original error: 'Command 'C:\\\\Users\\\\rutwik\\\\AppData\\\\Local\\\\Android\\\\Sdk\\\\platform-tools\\\\adb.exe -P 5037 -s 192.168.0.78\\:5555 shell 'settings delete global hidden_api_policy_pre_p_apps;settings delete global hidden_api_policy_p_apps;settings delete global hidden_api_policy'' exited with code 1'; Command output: adb.exe: device offline\r\n\nStacktrace:\nUnknownError: An unknown server-side error occurred while processing the command. Original error: Error executing adbExec. Original error: 'Command 'C:\\\\Users\\\\rutwik\\\\AppData\\\\Local\\\\Android\\\\Sdk\\\\platform-tools\\\\adb.exe -P 5037 -s 192.168.0.78\\:5555 shell 'settings delete global hidden_api_policy_pre_p_apps;settings delete global hidden_api_policy_p_apps;settings delete global hidden_api_policy'' exited with code 1'; Command output: adb.exe: device offline\r\n\n    at getResponseForW3CError (C:\\Users\\rutwik\\AppData\\Roaming\\npm\\node_modules\\appium\\node_modules\\@appium\\base-driver\\lib\\protocol\\errors.js:1143:9)\n    at asyncHandler (C:\\Users\\rutwik\\AppData\\Roaming\\npm\\node_modules\\appium\\node_modules\\@appium\\base-driver\\lib\\protocol\\protocol.js:485:57)\n", "trace": "  File \"C:\\Users\\rutwik\\miniconda3\\envs\\automation\\lib\\site-packages\\allure_commons\\_allure.py\", line 221, in __call__\n    return self._fixture_function(*args, **kwargs)\n  File \"C:\\Users\\rutwik\\miniconda3\\envs\\automation\\lib\\site-packages\\_pytest\\fixtures.py\", line 907, in _teardown_yield_fixture\n    next(it)\n  File \"C:\\Users\\rutwik\\Automation\\conftest.py\", line 60, in appium_driver\n    driver_instance.stop_driver()\n  File \"C:\\Users\\rutwik\\Automation\\conftest.py\", line 49, in stop_driver\n    self.driver.quit()\n  File \"C:\\Users\\rutwik\\miniconda3\\envs\\automation\\lib\\site-packages\\selenium\\webdriver\\remote\\webdriver.py\", line 589, in quit\n    self.execute(Command.QUIT)\n  File \"C:\\Users\\rutwik\\miniconda3\\envs\\automation\\lib\\site-packages\\selenium\\webdriver\\remote\\webdriver.py\", line 429, in execute\n    self.error_handler.check_response(response)\n  File \"C:\\Users\\rutwik\\miniconda3\\envs\\automation\\lib\\site-packages\\appium\\webdriver\\errorhandler.py\", line 125, in check_response\n    raise exception_class(msg=message, stacktrace=format_stacktrace(stacktrace))\n"}, "start": 1741887122052, "stop": 1741887122166}], "start": 1741887089298, "stop": 1741887122166}