{"name": "Select Takeout Order", "status": "failed", "statusDetails": {"message": "AssertionError: assert \"ERROR IS Message: An unknown server-side error occurred while processing the command. Original error: 'POST /element'...ata\\\\Roaming\\\\npm\\\\node_modules\\\\appium\\\\node_modules\\\\@appium\\\\base-driver\\\\lib\\\\basedriver\\\\commands\\\\find.ts:75:12)\" == True\n +  where \"ERROR IS Message: An unknown server-side error occurred while processing the command. Original error: 'POST /element'...ata\\\\Roaming\\\\npm\\\\node_modules\\\\appium\\\\node_modules\\\\@appium\\\\base-driver\\\\lib\\\\basedriver\\\\commands\\\\find.ts:75:12)\" = order('Take Out')\n +    where order = <logic.takeout_logic.Calculations object at 0x000001A1E78D5D20>.order\n +      where <logic.takeout_logic.Calculations object at 0x000001A1E78D5D20> = <test_cash.test_takeout_cash.TestTakeoutFlow object at 0x000001A1E9A0E530>.calc", "trace": "self = <test_cash.test_takeout_cash.TestTakeoutFlow object at 0x000001A1E9A0E530>\n\n    @allure.story(\"Order Management\")\n    @allure.title(\"Select Takeout Order\")\n    def test_take_out_btn(self):\n>       assert self.calc.order(\"Take Out\") == True\nE       assert \"ERROR IS Message: An unknown server-side error occurred while processing the command. Original error: 'POST /element'...ata\\\\Roaming\\\\npm\\\\node_modules\\\\appium\\\\node_modules\\\\@appium\\\\base-driver\\\\lib\\\\basedriver\\\\commands\\\\find.ts:75:12)\" == True\nE        +  where \"ERROR IS Message: An unknown server-side error occurred while processing the command. Original error: 'POST /element'...ata\\\\Roaming\\\\npm\\\\node_modules\\\\appium\\\\node_modules\\\\@appium\\\\base-driver\\\\lib\\\\basedriver\\\\commands\\\\find.ts:75:12)\" = order('Take Out')\nE        +    where order = <logic.takeout_logic.Calculations object at 0x000001A1E78D5D20>.order\nE        +      where <logic.takeout_logic.Calculations object at 0x000001A1E78D5D20> = <test_cash.test_takeout_cash.TestTakeoutFlow object at 0x000001A1E9A0E530>.calc\n\nsuits\\test_orderflows\\test_cash\\test_takeout_cash.py:22: AssertionError"}, "start": 1741885747903, "stop": 1741885747914, "uuid": "c8a475db-caae-4437-aa0a-5d5f6645b11b", "historyId": "1bbf2d31ea69aa75b953f1bf8ea58646", "testCaseId": "1bbf2d31ea69aa75b953f1bf8ea58646", "fullName": "suits.test_orderflows.test_cash.test_takeout_cash.TestTakeoutFlow#test_take_out_btn", "labels": [{"name": "story", "value": "Order Management"}, {"name": "feature", "value": "Takeout Order Flow"}, {"name": "parentSuite", "value": "suits.test_orderflows.test_cash"}, {"name": "suite", "value": "test_takeout_cash"}, {"name": "subSuite", "value": "TestTakeoutFlow"}, {"name": "host", "value": "LAPTOP-KKMKONCC"}, {"name": "thread", "value": "19520-MainThread"}, {"name": "framework", "value": "pytest"}, {"name": "language", "value": "cpython3"}, {"name": "package", "value": "suits.test_orderflows.test_cash.test_takeout_cash"}]}