{"uuid": "06243aae-5bd9-46de-a6bd-1541fb0b1d87", "children": ["3c349e72-11b6-45aa-b2b1-ea45207dd70b", "be08f02a-fd5f-457c-b11a-fadafd277e59", "e6ccda1b-5019-4084-90df-2f21662c5bd9", "3db1e06d-5144-4839-adc2-6277f554c302", "c9e913ba-fd11-4b64-b3e1-6b802c7dc3d3", "3d0ae37e-dc7a-46c8-8a82-e0b164e61fcc", "aaa877b8-d86b-48f0-bc71-7da098457357", "8305a94c-0d03-44fb-a2f2-780128e9d4ad", "6bc33630-72b0-4eb1-957f-e49b2a56c384", "66137806-0c7e-4b4d-88aa-8278ef80a032"], "befores": [{"name": "appium_driver", "status": "broken", "statusDetails": {"message": "selenium.common.exceptions.WebDriverException: Message: An unknown server-side error occurred while processing the command. Original error: The instrumentation process cannot be initialized. Make sure the application under test does not crash and investigate the logcat output.\nStacktrace:\nUnknownError: An unknown server-side error occurred while processing the command. Original error: The instrumentation process cannot be initialized. Make sure the application under test does not crash and investigate the logcat output.\n    at getResponseForW3CError (C:\\Users\\rutwik\\AppData\\Roaming\\npm\\node_modules\\appium\\node_modules\\@appium\\base-driver\\lib\\protocol\\errors.js:1143:9)\n    at asyncHandler (C:\\Users\\rutwik\\AppData\\Roaming\\npm\\node_modules\\appium\\node_modules\\@appium\\base-driver\\lib\\protocol\\protocol.js:485:57)\n", "trace": "  File \"C:\\Users\\rutwik\\miniconda3\\envs\\automation\\lib\\site-packages\\pluggy\\_callers.py\", line 167, in _multicall\n    teardown.throw(outcome._exception)\n  File \"C:\\Users\\rutwik\\miniconda3\\envs\\automation\\lib\\site-packages\\_pytest\\setuponly.py\", line 36, in pytest_fixture_setup\n    return (yield)\n  File \"C:\\Users\\rutwik\\miniconda3\\envs\\automation\\lib\\site-packages\\pluggy\\_callers.py\", line 103, in _multicall\n    res = hook_impl.function(*args)\n  File \"C:\\Users\\rutwik\\miniconda3\\envs\\automation\\lib\\site-packages\\_pytest\\fixtures.py\", line 1140, in pytest_fixture_setup\n    result = call_fixture_func(fixturefunc, request, kwargs)\n  File \"C:\\Users\\rutwik\\miniconda3\\envs\\automation\\lib\\site-packages\\_pytest\\fixtures.py\", line 891, in call_fixture_func\n    fixture_result = next(generator)\n  File \"C:\\Users\\rutwik\\Automation\\conftest.py\", line 58, in appium_driver\n    driver = driver_instance.start_driver()\n  File \"C:\\Users\\rutwik\\Automation\\conftest.py\", line 43, in start_driver\n    self.driver = webdriver.Remote(self.url, options=AppiumOptions().load_capabilities(self.caps))\n  File \"C:\\Users\\rutwik\\miniconda3\\envs\\automation\\lib\\site-packages\\appium\\webdriver\\webdriver.py\", line 227, in __init__\n    super().__init__(\n  File \"C:\\Users\\rutwik\\miniconda3\\envs\\automation\\lib\\site-packages\\selenium\\webdriver\\remote\\webdriver.py\", line 250, in __init__\n    self.start_session(capabilities)\n  File \"C:\\Users\\rutwik\\miniconda3\\envs\\automation\\lib\\site-packages\\appium\\webdriver\\webdriver.py\", line 319, in start_session\n    response = self.execute(RemoteCommand.NEW_SESSION, w3c_caps)\n  File \"C:\\Users\\rutwik\\miniconda3\\envs\\automation\\lib\\site-packages\\selenium\\webdriver\\remote\\webdriver.py\", line 429, in execute\n    self.error_handler.check_response(response)\n  File \"C:\\Users\\rutwik\\miniconda3\\envs\\automation\\lib\\site-packages\\selenium\\webdriver\\remote\\errorhandler.py\", line 232, in check_response\n    raise exception_class(message, screen, stacktrace)\n"}, "start": 1741885757662, "stop": 1741885768985}], "start": 1741885757662, "stop": 1741885770401}