{"uuid": "9a7be73f-94f5-4ff4-9766-1b69c5f2a0a9", "children": ["fdcc7e7a-fb37-4fce-a44e-0bbd72c15445", "d97952ff-ff89-4ccf-b77c-7cafc388cbc9", "da0ff31e-528f-4999-ae90-5a93f44c4334", "dbcbaebb-fe2d-4d86-bc60-204a1ebaa3d3", "3e1e08b0-598f-4892-af4f-1b77649bb5b1", "c7680f3f-1557-4bb3-80ff-dc8cc4e9e1af", "5a4a0742-57af-4863-8b23-3e418e35f58f", "776c10c2-3602-46e1-8306-c13a8a50d85a", "a56b9694-c6cb-42ee-98af-242ae0ee864d", "53d77e04-398e-473b-865a-7ca92f35f8b6"], "befores": [{"name": "appium_driver", "status": "broken", "statusDetails": {"message": "selenium.common.exceptions.WebDriverException: Message: An unknown server-side error occurred while processing the command. Original error: The instrumentation process cannot be initialized. Make sure the application under test does not crash and investigate the logcat output.\nStacktrace:\nUnknownError: An unknown server-side error occurred while processing the command. Original error: The instrumentation process cannot be initialized. Make sure the application under test does not crash and investigate the logcat output.\n    at getResponseForW3CError (C:\\Users\\rutwik\\AppData\\Roaming\\npm\\node_modules\\appium\\node_modules\\@appium\\base-driver\\lib\\protocol\\errors.js:1143:9)\n    at asyncHandler (C:\\Users\\rutwik\\AppData\\Roaming\\npm\\node_modules\\appium\\node_modules\\@appium\\base-driver\\lib\\protocol\\protocol.js:485:57)\n", "trace": "  File \"C:\\Users\\rutwik\\miniconda3\\envs\\automation\\lib\\site-packages\\pluggy\\_callers.py\", line 167, in _multicall\n    teardown.throw(outcome._exception)\n  File \"C:\\Users\\rutwik\\miniconda3\\envs\\automation\\lib\\site-packages\\_pytest\\setuponly.py\", line 36, in pytest_fixture_setup\n    return (yield)\n  File \"C:\\Users\\rutwik\\miniconda3\\envs\\automation\\lib\\site-packages\\pluggy\\_callers.py\", line 103, in _multicall\n    res = hook_impl.function(*args)\n  File \"C:\\Users\\rutwik\\miniconda3\\envs\\automation\\lib\\site-packages\\_pytest\\fixtures.py\", line 1140, in pytest_fixture_setup\n    result = call_fixture_func(fixturefunc, request, kwargs)\n  File \"C:\\Users\\rutwik\\miniconda3\\envs\\automation\\lib\\site-packages\\_pytest\\fixtures.py\", line 891, in call_fixture_func\n    fixture_result = next(generator)\n  File \"C:\\Users\\rutwik\\Automation\\conftest.py\", line 58, in appium_driver\n    driver = driver_instance.start_driver()\n  File \"C:\\Users\\rutwik\\Automation\\conftest.py\", line 43, in start_driver\n    self.driver = webdriver.Remote(self.url, options=AppiumOptions().load_capabilities(self.caps))\n  File \"C:\\Users\\rutwik\\miniconda3\\envs\\automation\\lib\\site-packages\\appium\\webdriver\\webdriver.py\", line 227, in __init__\n    super().__init__(\n  File \"C:\\Users\\rutwik\\miniconda3\\envs\\automation\\lib\\site-packages\\selenium\\webdriver\\remote\\webdriver.py\", line 250, in __init__\n    self.start_session(capabilities)\n  File \"C:\\Users\\rutwik\\miniconda3\\envs\\automation\\lib\\site-packages\\appium\\webdriver\\webdriver.py\", line 319, in start_session\n    response = self.execute(RemoteCommand.NEW_SESSION, w3c_caps)\n  File \"C:\\Users\\rutwik\\miniconda3\\envs\\automation\\lib\\site-packages\\selenium\\webdriver\\remote\\webdriver.py\", line 429, in execute\n    self.error_handler.check_response(response)\n  File \"C:\\Users\\rutwik\\miniconda3\\envs\\automation\\lib\\site-packages\\selenium\\webdriver\\remote\\errorhandler.py\", line 232, in check_response\n    raise exception_class(message, screen, stacktrace)\n"}, "start": 1741885804425, "stop": 1741885811304}], "start": 1741885804425, "stop": 1741885812779}