{"uuid": "09b366f4-03ed-44f3-9ff9-c4c8f12de7da", "children": ["030a737e-b914-4f6d-9bed-1017b3a957e7"], "befores": [{"name": "appium_driver", "status": "broken", "statusDetails": {"message": "selenium.common.exceptions.WebDriverException: Message: An unknown server-side error occurred while processing the command. Original error: Could not find a connected Android device in 20000ms\nStacktrace:\nUnknownError: An unknown server-side error occurred while processing the command. Original error: Could not find a connected Android device in 20000ms\n    at getResponseForW3CError (C:\\Users\\rutwik\\AppData\\Roaming\\npm\\node_modules\\appium\\node_modules\\@appium\\base-driver\\lib\\protocol\\errors.js:1143:9)\n    at asyncHandler (C:\\Users\\rutwik\\AppData\\Roaming\\npm\\node_modules\\appium\\node_modules\\@appium\\base-driver\\lib\\protocol\\protocol.js:485:57)\n", "trace": "  File \"C:\\Users\\rutwik\\miniconda3\\Lib\\site-packages\\pluggy\\_callers.py\", line 167, in _multicall\n    teardown.throw(outcome._exception)\n  File \"C:\\Users\\rutwik\\miniconda3\\Lib\\site-packages\\_pytest\\setuponly.py\", line 36, in pytest_fixture_setup\n    return (yield)\n            ^^^^^\n  File \"C:\\Users\\rutwik\\miniconda3\\Lib\\site-packages\\pluggy\\_callers.py\", line 103, in _multicall\n    res = hook_impl.function(*args)\n          ^^^^^^^^^^^^^^^^^^^^^^^^^\n  File \"C:\\Users\\rutwik\\miniconda3\\Lib\\site-packages\\_pytest\\fixtures.py\", line 1140, in pytest_fixture_setup\n    result = call_fixture_func(fixturefunc, request, kwargs)\n             ^^^^^^^^^^^^^^^^^^^^^^^^^^^^^^^^^^^^^^^^^^^^^^^\n  File \"C:\\Users\\rutwik\\miniconda3\\Lib\\site-packages\\_pytest\\fixtures.py\", line 891, in call_fixture_func\n    fixture_result = next(generator)\n                     ^^^^^^^^^^^^^^^\n  File \"C:\\Users\\rutwik\\Automation\\conftest.py\", line 58, in appium_driver\n    driver = driver_instance.start_driver()\n             ^^^^^^^^^^^^^^^^^^^^^^^^^^^^^^\n  File \"C:\\Users\\rutwik\\Automation\\conftest.py\", line 43, in start_driver\n    self.driver = webdriver.Remote(self.url, options=AppiumOptions().load_capabilities(self.caps))\n                  ^^^^^^^^^^^^^^^^^^^^^^^^^^^^^^^^^^^^^^^^^^^^^^^^^^^^^^^^^^^^^^^^^^^^^^^^^^^^^^^^\n  File \"C:\\Users\\rutwik\\miniconda3\\Lib\\site-packages\\appium\\webdriver\\webdriver.py\", line 227, in __init__\n    super().__init__(\n  File \"C:\\Users\\rutwik\\miniconda3\\Lib\\site-packages\\selenium\\webdriver\\remote\\webdriver.py\", line 250, in __init__\n    self.start_session(capabilities)\n  File \"C:\\Users\\rutwik\\miniconda3\\Lib\\site-packages\\appium\\webdriver\\webdriver.py\", line 319, in start_session\n    response = self.execute(RemoteCommand.NEW_SESSION, w3c_caps)\n               ^^^^^^^^^^^^^^^^^^^^^^^^^^^^^^^^^^^^^^^^^^^^^^^^^\n  File \"C:\\Users\\rutwik\\miniconda3\\Lib\\site-packages\\selenium\\webdriver\\remote\\webdriver.py\", line 429, in execute\n    self.error_handler.check_response(response)\n  File \"C:\\Users\\rutwik\\miniconda3\\Lib\\site-packages\\selenium\\webdriver\\remote\\errorhandler.py\", line 232, in check_response\n    raise exception_class(message, screen, stacktrace)\n"}, "start": 1742289626602, "stop": 1742289647091}], "start": 1742289626602, "stop": 1742289647436}